Workbook

Sheet Exercise Master
A1: ADVENTURE RACING — EXERCISE MASTER DATABASE
A2: Exercise ID | B2: Exercise Name | C2: Exercise Type | D2: Movement Pattern | E2: Primary Muscles | F2: Secondary Muscles | G2: Equipment | H2: Novelty | I2: Injury Flags / Points of Failure | J2: Notes / Coaching Cues | K2: Equipment Substitutes | L2: Physical Proxy Exercises | M2: Contraindicated Body Parts | N2: Progression Exercise | O2: Regression Exercise | P2: Sport Count
A3: EX001 | B3: Back Squat (Barbell) | C3: Strength | D3: Squat | E3: Quadriceps, Glutes | F3: Hamstrings, Erector Spinae, Core | G3: Barbell, Squat rack | H3: Common | I3: Knee — valgus collapse; Lumbar — flexion under load; Shoulder/Wrist — bar rack mobility | J3: Brace before descent; knees track toes; chest up; foundational lower-body load | K3: Safety Bar Squat; Hack Squat machine; Smith Machine Squat; 🏠 Backpack loaded with books or water (goblet hold) for hotel squat | L3: EX002 — Goblet Squat (DB/KB); EX037 — Wall Sit | M3: Knee, Lumbar, Shoulder/Wrist | O3: EX002 — Goblet Squat (DB/KB) | P3: =COUNTIF('Sport-Exercise Map'!A:A,A3)
A4: EX002 | B4: Goblet Squat (DB/KB) | C4: Strength | D4: Squat | E4: Quadriceps, Glutes | F4: Core, Upper Back | G4: Dumbbell, Kettlebell | H4: Common | I4: Knee — valgus at depth; Wrist — grip discomfort under fatigue | J4: Counterbalance keeps torso upright; best hotel substitute for back squat | K4: Bodyweight squat (no load); Sandbag Goblet Squat; 🏠 Gallon water jug (~8.5 lb) as light goblet load; filled suitcase held at chest | L4: EX037 — Wall Sit; EX022 — Reverse Lunge (DB or BW) | M4: Knee, Wrist | N4: EX001 — Back Squat (Barbell) | P4: =COUNTIF('Sport-Exercise Map'!A:A,A4)
A5: EX003 | B5: Romanian Deadlift (Barbell) | C5: Strength | D5: Hinge | E5: Hamstrings, Glutes | F5: Erector Spinae, Forearms | G5: Barbell | H5: Common | I5: Lumbar — rounding under load; Hamstring — overstretching if flexibility limited | J5: Neutral spine; hinge at hip not waist; bar stays close to legs | K5: DB Romanian Deadlift; KB Deadlift; Trap Bar Deadlift; 🏠 Filled suitcase as barbell substitute (held at mid-thigh); backpack deadlift | L5: EX004 — Single-Leg RDL (DB); EX031 — Kettlebell Swing (Two-Hand) | M5: Lumbar, Hamstring | N5: EX020 — Nordic Hamstring Curl | P5: =COUNTIF('Sport-Exercise Map'!A:A,A5)
A6: EX004 | B6: Single-Leg RDL (DB) | C6: Strength | D6: Hinge, Single-Leg | E6: Glutes, Hamstrings | F6: Core, Hip Stabilisers | G6: Dumbbell | H6: Common | I6: Ankle — instability; Lumbar — rotation under fatigue; Hip — drop on standing side | J6: Slow eccentric critical for trail stability transfer; plant foot softly bent | K6: KB Single-Leg RDL; Single-Leg Good Morning (bodyweight); 🏠 Gallon water jug as light DB; bodyweight single-leg RDL (balance focus) | L6: EX039 — Glute Bridge (Double-Leg); EX019 — Barbell Hip Thrust | M6: Ankle, Lumbar, Hip | N6: EX117 — Loaded Step-Down (Eccentric Box) | P6: =COUNTIF('Sport-Exercise Map'!A:A,A6)
A7: EX005 | B7: Dead Hang | C7: Isometric | D7: Pull-V | E7: Grip, Forearms, Lats | F7: Shoulder Girdle, Core | G7: Pull-Up Bar, Hangboard | H7: Common | I7: Shoulder — impingement if passive hang without engagement; Wrist — extension load | J7: Actively pack shoulders; builds grip endurance for climbing and paddle holds | K7: Door frame hang; Towel-over-bar hang; Gymnastics rings; 🏠 Sturdy door frame; playground monkey bars; tree branch (test before full weight); stairwell railing overhang | L7: EX084 — Scapular Depression Hold; EX106 — Lock-Off Hold | M7: Shoulder, Wrist | N7: EX100 — Hangboard Half-Crimp Hold | O7: EX084 — Scapular Depression Hold | P7: =COUNTIF('Sport-Exercise Map'!A:A,A7)
A8: EX006 | B8: Pull-Up (BW) | C8: Strength | D8: Pull-V | E8: Latissimus Dorsi, Biceps | F8: Rear Delts, Core, Forearms | G8: Pull-Up Bar | H8: Common | I8: Shoulder — anterior capsule stress with excessive forward lean; Elbow — medial stress (wide grip) | J8: Full ROM; 3s eccentric for climbing carryover; supinated grip = chin-up | K8: Band-assisted Pull-Up; TRX Row (horizontal sub); Ring Row; 🏠 Playground bar or sturdy tree branch; parking garage beam (concrete); hotel room door-mount pull-up bar | L8: EX080 — Lat Pulldown (Wide Grip); EX078 — Single-Arm DB Row | M8: Shoulder, Elbow | N8: EX106 — Lock-Off Hold (90°, 120°) | O8: EX005 — Dead Hang | P8: =COUNTIF('Sport-Exercise Map'!A:A,A8)
A9: EX007 | B9: Box Jump | C9: Plyometric | D9: Squat, Hip-Ext | E9: Glutes, Quadriceps, Calves | F9: Hamstrings, Core | G9: Plyo box | H9: Common | I9: Ankle — landing mechanics; Knee — valgus on landing; Achilles — reactive load | J9: Land soft with hip hinge; step down, never jump down | K9: Step-up box jump (lower box); Stair jump; 🏠 Stair step or park bench for lower box jump; hotel bed (careful — test stability first) | L9: EX032 — Jump Squat (BW or Light Load); EX008 — Broad Jump | M9: Ankle, Knee, Achilles | N9: EX033 — Depth Drop (Eccentric Landing Practice) | O9: EX032 — Jump Squat (BW or Light Load) | P9: =COUNTIF('Sport-Exercise Map'!A:A,A9)
A10: EX008 | B10: Broad Jump | C10: Plyometric | D10: Hip-Ext, Locomotion | E10: Glutes, Hamstrings, Calves | F10: Core, Quads | H10: Common | I10: Ankle — landing impact; Knee — hyperextension on stick landing | J10: Max horizontal power; stick each landing; useful as field test metric | K10: Marked floor for distance; Sand or grass for impact reduction; 🏠 No equipment needed; mark distance with tape, shoes, or chalk | L10: EX007 — Box Jump; EX034 — Lateral Bound | M10: Ankle, Knee | N10: EX007 — Box Jump | O10: EX035 — Ankle Hops / Pogo Jumps | P10: =COUNTIF('Sport-Exercise Map'!A:A,A10)
A11: EX009 | B11: Farmer Carry | C11: Loaded Carry | D11: Carry | E11: Grip, Forearms, Trapezius | F11: Core, Glutes, Calves | G11: Dumbbell, Kettlebell, Barbell | H11: Common | I11: Lumbar — lateral flexion with asymmetric load; Shoulder — trap overload heavy loads | J11: Pack-carry sim; shoulders packed; tall gait; suitcase carry for unilateral demand | K11: Suitcase carry (one DB); Loaded backpack carry; Sandbag carry; 🏠 Gallon jugs in each hand; filled grocery bags; suitcases | L11: EX010 — Rucking (Weighted Hike); EX095 — Portage Carry Simulation | M11: Lumbar, Shoulder | N11: EX010 — Rucking (Weighted Hike) | P11: =COUNTIF('Sport-Exercise Map'!A:A,A11)
A12: EX010 | B12: Rucking (Weighted Hike) | C12: Loaded Carry | D12: Locomotion, Carry | E12: Glutes, Hamstrings, Calves | F12: Erector Spinae, Core, Quads | G12: Backpack, Weighted vest | H12: Common | I12: Hip Flexor — shortening under sustained load; Knee — patellofemoral on descents; Shoulder/Neck — pack fit | J12: Primary race-sim for foot legs; monitor foot hot spots; keep HR aerobic | K12: Stair climb with pack; Weighted vest walk; 🏠 Backpack loaded with books, water bottles, or bag of rice; weighted vest alternative: load a hydration pack with water | L12: EX009 — Farmer Carry; EX050 — Treadmill Incline Walk (Loaded Pack) | M12: Hip Flexor, Knee, Shoulder/Neck | N12: EX120 — Sustained LISS (Hiking Pace) | O12: EX050 — Treadmill Incline Walk (Loaded Pack) | P12: =COUNTIF('Sport-Exercise Map'!A:A,A12)
A13: EX011 | B13: Pallof Press (Band/Cable) | C13: Isometric | D13: Anti-Rotation | E13: Obliques, Transverse Abdominis | F13: Glutes, Hip Flexors | G13: Resistance band, Cable machine | H13: Common | I13: Shoulder — instability if set too wide; Lumbar — rotation if core not braced | J13: Anti-rotation; builds kayak/paddle torso stability; hips square throughout | K13: Half-kneeling band version (rotation not anti-rotation); Landmine Pallof; 🏠 Band anchored in closed door at chest height; or hug a heavy backpack and resist rotation standing | L13: EX089 — Hollow Body Hold; EX088 — Russian Twist (DB / Med Ball) | M13: Shoulder, Lumbar | N13: EX087 — Cable High-to-Low Chop | P13: =COUNTIF('Sport-Exercise Map'!A:A,A13)
A14: EX012 | B14: Copenhagen Plank | C14: Isometric | D14: Anti-Adduction, Single-Leg | E14: Hip Adductors, Obliques | F14: Glutes, Core | G14: Bench, Plyo box | H14: Specialized | I14: Groin — adductor strain if loaded too early; Hip — lateral capsule stress | J14: Top foot on bench; groin injury prevention; underused across most sports | K14: Side-lying hip adduction (no bench); Adductor squeeze (ball between knees); 🏠 Bed edge or chair seat for top foot elevation | L14: EX023 — Lateral Lunge (DB or BW); EX040 — Clamshell (Band) | M14: Groin, Hip | P14: =COUNTIF('Sport-Exercise Map'!A:A,A14)
A15: EX013 | B15: Hip Circle (Band) | C15: Activation / Primer | D15: Hip-Ext, Rotation | E15: Glute Med, Glute Max | F15: Hip Abductors | G15: Resistance band | H15: Common | I15: Hip — impingement at extreme range if rushed | J15: Pre-run/hike glute activation; controlled ROM not speed | K15: Standing hip circle without band; 🏠 Loop a towel or belt around knees as improvised band; no equipment for unresisted version | L15: EX040 — Clamshell (Band); EX039 — Glute Bridge (Double-Leg) | M15: Hip | N15: EX017 — Lateral Band Walk | P15: =COUNTIF('Sport-Exercise Map'!A:A,A15)
A16: EX014 | B16: World's Greatest Stretch | C16: Mobility | D16: Squat, Rotation, Hip-Ext | E16: Hip Flexors, Thoracic Spine, Hamstrings | F16: Glutes, Groin, Shoulders | H16: Common | I16: Knee — medial stress if front foot collapses; Wrist — load on hard surface | J16: Highest-yield single mobility drill; integrates lower and upper chain | K16: 🏠 No equipment needed | L16: EX015 — Pigeon Pose; EX046 — Hip Flexor Lunge Stretch | M16: Knee, Wrist | P16: =COUNTIF('Sport-Exercise Map'!A:A,A16)
A17: EX015 | B17: Pigeon Pose | C17: Flexibility / Stretching | D17: Hip-Ext | E17: Piriformis, Glutes, Hip External Rotators | F17: IT Band, Hip Flexors | H17: Common | I17: Knee — meniscus/ligament stress if torqued; Hip — SI joint irritation if pelvis not level | J17: Keep hips square; pad under hip if needed; 90s+ holds for tissue adaptation | K17: Supine figure-4 stretch (floor sub for pigeon); Thread-the-needle; 🏠 Folded towel under hip for comfort; hotel bed corner for elevated pigeon | L17: EX046 — Hip Flexor Lunge Stretch; EX014 — World's Greatest Stretch | M17: Knee, Hip | P17: =COUNTIF('Sport-Exercise Map'!A:A,A17)
A18: EX016 | B18: Thoracic Rotation Drill | C18: Mobility | D18: Rotation | E18: Thoracic Erectors, Obliques | F18: Lats, Rear Delts | H18: Common | I18: Lumbar — compensatory rotation if thoracic locked | J18: Side-lying or quadruped; keep hips still to isolate T-spine; critical for paddle and climbing | K18: Side-lying thoracic rotation (wall sub); 🏠 No equipment needed; lie on hotel bed for side-lying version | L18: EX065 — Scapular Wall Slide; EX014 — World's Greatest Stretch | M18: Lumbar | P18: =COUNTIF('Sport-Exercise Map'!A:A,A18)
A19: EX017 | B19: Lateral Band Walk | C19: Activation / Primer | D19: Hip-Ext, Abduction | E19: Glute Medius, Glute Minimus | F19: Hip Abductors, TFL | G19: Resistance band | H19: Common | I19: Knee — valgus if band too high pulls inward | J19: Band above knees for knee stability; below knee for more hip demand; pre-run staple | K19: Theraband substitution; Lateral walk without band (reduced stimulus); 🏠 Towel or belt loop around ankles; hair tie or rubber bands doubled as light resistance | L19: EX040 — Clamshell (Band); EX041 — Monster Walk (Band) | M19: Knee | N19: EX041 — Monster Walk (Band) | O19: EX040 — Clamshell (Band) | P19: =COUNTIF('Sport-Exercise Map'!A:A,A19)
A20: EX018 | B20: Foam Roll (IT Band / Quads / Lats) | C20: Recovery / Soft Tissue | D20: Stretch | E20: IT Band, Quadriceps, Lats | F20: TFL, Glutes | G20: Foam Roller | H20: Common | I20: Knee — avoid rolling directly on lateral knee; Hip — bursa near greater trochanter | J20: Slow passes; 10–20s on tender spots; post-run, post-bike, post-hike recovery | K20: Lacrosse ball (targeted); Massage gun; Stick roller; 🏠 Tennis ball, lacrosse ball, or water bottle for targeted rolling; rolled-up towel under IT band; massage gun if available | L20: EX015 — Pigeon Pose; EX046 — Hip Flexor Lunge Stretch | M20: Knee, Hip | P20: =COUNTIF('Sport-Exercise Map'!A:A,A20)
A21: EX019 | B21: Barbell Hip Thrust | C21: Strength | D21: Hip-Ext | E21: Glutes | F21: Hamstrings, Core, Hip Flexors | G21: Barbell, Bench | H21: Common | I21: Lumbar — hyperextension at top; Hip — anterior impingement with poor setup | J21: Drive through heels; full hip lock at top; best glute isolator before loaded carries | K21: Single-Leg Hip Thrust; KB Hip Thrust; Barbell on bench (no rack); 🏠 Single-leg hip thrust on hotel bed edge; backpack across hips for load | L21: EX039 — Glute Bridge (Double-Leg); EX004 — Single-Leg RDL (DB) | M21: Lumbar, Hip | O21: EX039 — Glute Bridge (Double-Leg) | P21: =COUNTIF('Sport-Exercise Map'!A:A,A21)
A22: EX020 | B22: Nordic Hamstring Curl | C22: Strength | D22: Hinge | E22: Hamstrings (eccentric emphasis) | F22: Glutes, Calves | H22: Specialized | I22: Hamstring — high DOMS initially; Knee — patellar tendon stress at full extension | J22: Most evidence-backed hamstring injury prevention drill; eccentric load; progress slowly | K22: Nordic on bed anchor (feet under bed frame); Sliding disc hamstring curl; 🏠 Feet anchored under bed frame or heavy dresser; towel-assisted Nordic on smooth floor | L22: EX117 — Loaded Step-Down (Eccentric Box); EX004 — Single-Leg RDL (DB) | M22: Hamstring, Knee | O22: EX003 — Romanian Deadlift (Barbell) | P22: =COUNTIF('Sport-Exercise Map'!A:A,A22)
A23: EX021 | B23: Bulgarian Split Squat (DB) | C23: Strength | D23: Single-Leg, Squat | E23: Quadriceps, Glutes | F23: Hamstrings, Hip Stabilisers, Core | G23: Dumbbell | H23: Common | I23: Knee — anterior pain if shin too vertical; Hip Flexor — impingement at bottom; Ankle — rear foot instability | J23: Rear foot elevated; front foot far enough forward to keep shin vertical; best overall lower body exercise for AR | K23: Barbell Bulgarian Split Squat (if rack available); Sandbag on shoulder; 🏠 Chair or bed edge for rear foot elevation; backpack for load; stair step as platform | L23: EX022 — Reverse Lunge (DB or BW); EX038 — Split Squat ISO Hold | M23: Knee, Hip Flexor, Ankle | N23: EX028 — Pistol Squat / Assisted Pistol | O23: EX022 — Reverse Lunge (DB or BW) | P23: =COUNTIF('Sport-Exercise Map'!A:A,A23)
A24: EX022 | B24: Reverse Lunge (DB or BW) | C24: Strength | D24: Single-Leg, Squat | E24: Quadriceps, Glutes | F24: Hamstrings, Hip Stabilisers | G24: Dumbbell, Kettlebell | H24: Common | I24: Knee — patellar tracking if step too short; Hip — anterior impingement at bottom | J24: Step back not forward — reduces knee shear; better proprioceptive challenge than forward lunge | K24: Barbell Reverse Lunge; Sandbag Lunge; 🏠 Backpack for load; gallon jugs in each hand | L24: EX038 — Split Squat ISO Hold; EX039 — Glute Bridge (Double-Leg) | M24: Knee, Hip | N24: EX021 — Bulgarian Split Squat (DB) | P24: =COUNTIF('Sport-Exercise Map'!A:A,A24)
A25: EX023 | B25: Lateral Lunge (DB or BW) | C25: Strength | D25: Single-Leg, Abduction | E25: Glutes, Quads, Groin | F25: Hamstrings, Hip Stabilisers | G25: Dumbbell, Kettlebell | H25: Common | I25: Groin — adductor strain if range increases too fast; Knee — medial stress if loading knee collapses | J25: Sit into hip of working leg; non-working leg stays straight; critical for lateral terrain and climbing moves | K25: Barbell Lateral Lunge; Bodyweight lateral lunge (no load); 🏠 Gallon jugs in each hand for light lateral lunge load | L25: EX012 — Copenhagen Plank; EX040 — Clamshell (Band) | M25: Groin, Knee | P25: =COUNTIF('Sport-Exercise Map'!A:A,A25)
A26: EX024 | B26: Step-Up High Box (Loaded) | C26: Strength | D26: Single-Leg, Hip-Ext | E26: Glutes, Quadriceps | F26: Hamstrings, Core | G26: Dumbbell, Barbell, Weighted vest | H26: Common | I26: Knee — anterior stress if pushing off bottom foot; Hip — flexor impingement at top if box too high | J26: Drive through heel of working foot only; don't push off bottom foot; use 20–24" box | K26: Barbell Step-Up; Loaded backpack step-up; 🏠 Stair step, park bench, or sturdy chair as box; backpack for load | L26: EX119 — Weighted Step-Up (High Box, Heavy Load); EX021 — Bulgarian Split Squat | M26: Knee, Hip | N26: EX119 — Weighted Step-Up (High Box, Heavy Load) | P26: =COUNTIF('Sport-Exercise Map'!A:A,A26)
A27: EX025 | B27: Single-Leg Calf Raise (Loaded) | C27: Strength | D27: Hip-Ext | E27: Gastrocnemius, Soleus | F27: Peroneal Muscles, Plantar Fascia | G27: Dumbbell, Kettlebell | H27: Common | I27: Achilles — tendinopathy risk with rapid load increase; Plantar Fascia — stress at push-off | J27: Full ROM: deep stretch at bottom, strong lockout at top; use step edge for full range | K27: Smith Machine Calf Raise; Leg Press calf raise; Barbell calf raise; 🏠 Stair edge for full ROM calf raise; curb; thick book on floor; doorway threshold | L27: EX026 — Seated Calf Raise; EX035 — Ankle Hops / Pogo Jumps | M27: Achilles, Plantar Fascia | N27: EX035 — Ankle Hops / Pogo Jumps | O27: EX026 — Seated Calf Raise | P27: =COUNTIF('Sport-Exercise Map'!A:A,A27)
A28: EX026 | B28: Seated Calf Raise | C28: Strength | D28: Hip-Ext | E28: Soleus | F28: Tibialis Posterior | G28: Barbell | H28: Common | I28: Achilles — tendon stress if loaded too heavy too fast | J28: Bent knee isolates soleus — the fatigue-limiting muscle in distance running and hiking; underrated | K28: Barbell across thighs (no machine); Smith Machine Seated Calf Raise; 🏠 Seated on chair with heavy backpack across knees; gallon jugs on thighs | L28: EX025 — Single-Leg Calf Raise (Loaded); EX035 — Ankle Hops / Pogo Jumps | M28: Achilles | N28: EX025 — Single-Leg Calf Raise (Loaded) | P28: =COUNTIF('Sport-Exercise Map'!A:A,A28)
A29: EX027 | B29: Tibialis Raise (Wall or Machine) | C29: Strength | D29: Hip-Ext | E29: Tibialis Anterior | F29: Extensor Digitorum Longus | G29: Resistance band | H29: Specialized | I29: Shin — anterior compartment DOMS on introduction; Ankle — dorsiflexion ROM restriction | J29: Heels against wall, dorsiflex toes toward shin; best shin splint prevention exercise; novel to most athletes | K29: Seated tibialis raise (plate on toe); Band dorsiflexion; 🏠 Heels on stair edge, dorsiflex toes toward shins; no equipment needed for wall version | L29: EX035 — Ankle Hops / Pogo Jumps; EX045 — Ankle Mobility Drill (Wall) | M29: Shin, Ankle | P29: =COUNTIF('Sport-Exercise Map'!A:A,A29)
A30: EX028 | B30: Pistol Squat / Assisted Pistol | C30: Strength | D30: Single-Leg, Squat | E30: Quadriceps, Glutes | F30: Hip Stabilisers, Core, Ankle Dorsiflexors | G30: TRX / suspension trainer | H30: Specialized | I30: Knee — high patellar tendon load at bottom; Ankle — dorsiflexion restriction limits depth; Hip — impingement at full squat | J30: Use TRX or pole assist until strong enough; ankle mobility usually the limiting factor; mimics steep descent and high-step climbing | K30: TRX-assisted Pistol Squat; Pole-assisted Pistol Squat; 🏠 Doorframe or chair back for balance assist; no equipment needed for bodyweight version | L30: EX021 — Bulgarian Split Squat (DB); EX043 — Single-Leg Balance Hold | M30: Knee, Ankle, Hip | O30: EX021 — Bulgarian Split Squat (DB) | P30: =COUNTIF('Sport-Exercise Map'!A:A,A30)
A31: EX029 | B31: Sled Push | C31: Power | D31: Locomotion | E31: Quadriceps, Glutes, Calves | F31: Core, Hip Flexors | G31: Weighted Sled | H31: Common | I31: Hip Flexor — at full extension during push; Achilles — loading on drive phase | J31: No eccentric — ideal for accumulating leg volume without soreness; great for AR base phase | K31: Band sprint drill (resistance band anchored behind); Prowler (same pattern) | L31: EX031 — Kettlebell Swing (Two-Hand); EX007 — Box Jump | M31: Hip Flexor, Achilles | N31: EX031 — Kettlebell Swing (Two-Hand) | P31: =COUNTIF('Sport-Exercise Map'!A:A,A31)
A32: EX030 | B32: Reverse Sled Drag | C32: Strength | D32: Single-Leg, Squat | E32: Quadriceps (eccentric), VMO | F32: Hip Flexors, Core | G32: Weighted Sled | H32: Specialized | I32: Knee — patellar tendon if too heavy; Quad — significant DOMS on introduction | J32: Walk backward with sled; mimics downhill braking load without injury risk; builds VMO eccentric control | K32: Band walk-back (resistance band substitution for sled) | L32: EX020 — Nordic Hamstring Curl; EX117 — Loaded Step-Down (Eccentric Box) | M32: Knee, Quad | P32: =COUNTIF('Sport-Exercise Map'!A:A,A32)
A33: EX031 | B33: Kettlebell Swing (Two-Hand) | C33: Power | D33: Hinge, Hip-Ext | E33: Glutes, Hamstrings | F33: Erector Spinae, Core, Forearms | G33: Kettlebell | H33: Common | I33: Lumbar — flexion if hip hinge breaks down; Shoulder — impingement if arms too high; Wrist — extension load at top | J33: Hip hinge drives swing — not a squat; keep lats engaged; float at top not a press; high metabolic demand | K33: DB Swing; Single-arm KB Swing; 🏠 Filled suitcase or heavy backpack for improvised KB swing (two-hand grip on handle); gallon jug | L33: EX032 — Jump Squat (BW or Light Load); EX007 — Box Jump | M33: Lumbar, Shoulder, Wrist | O33: EX029 — Sled Push | P33: =COUNTIF('Sport-Exercise Map'!A:A,A33)
A34: EX032 | B34: Jump Squat (BW or Light Load) | C34: Power | D34: Squat, Hip-Ext | E34: Glutes, Quadriceps | F34: Hamstrings, Calves, Core | G34: Weighted vest | H34: Common | I34: Ankle — landing impact; Knee — valgus on landing; Lumbar — axial compression (loaded version) | J34: Land soft with hip hinge; keep load < 20% 1RM if loaded; rate of force development is the goal | K34: Barbell Jump Squat (< 20% 1RM); Sandbag Jump Squat; 🏠 No equipment needed for bodyweight version; backpack for light load | L34: EX007 — Box Jump; EX031 — Kettlebell Swing (Two-Hand) | M34: Ankle, Knee, Lumbar | N34: EX007 — Box Jump | P34: =COUNTIF('Sport-Exercise Map'!A:A,A34)
A35: EX033 | B35: Depth Drop (Eccentric Landing Practice) | C35: Plyometric | D35: Squat, Single-Leg | E35: Quadriceps (eccentric), Glutes | F35: Hamstrings, Ankle Stabilisers | G35: Plyo box | H35: Specialized | I35: Knee — high load if landing stiff; Ankle — impact with poor mechanics; Achilles — reactive stress | J35: Step off box, stick landing quietly; progress to single-leg; teaches soft landing critical for downhill trail | K35: Stair step-off (lower height); Curb depth drop; 🏠 Stair step or curb for low-height depth drop; park bench (test stability) | L35: EX117 — Loaded Step-Down (Eccentric Box); EX020 — Nordic Hamstring Curl | M35: Knee, Ankle, Achilles | O35: EX007 — Box Jump | P35: =COUNTIF('Sport-Exercise Map'!A:A,A35)
A36: EX034 | B36: Lateral Bound | C36: Plyometric | D36: Single-Leg, Locomotion | E36: Glutes, Quads, Calves | F36: Hip Abductors, Core | H36: Common | I36: Ankle — inversion sprain on landing; Knee — valgus if glutes not engaged; Groin — adductor strain wide landing | J36: Single-leg takeoff and landing; stick each landing; mimics rocky trail lateral foot adjustment | K36: Lateral hop over line (marked floor); Mini hurdle lateral hop; 🏠 No equipment needed; mark landing targets with tape or shoes | L36: EX055 — Lateral Shuffle Sprint; EX023 — Lateral Lunge (DB or BW) | M36: Ankle, Knee, Groin | N36: EX036 — Running Bounds (Exaggerated Stride) | P36: =COUNTIF('Sport-Exercise Map'!A:A,A36)
A37: EX035 | B37: Ankle Hops / Pogo Jumps | C37: Plyometric | D37: Locomotion | E37: Gastrocnemius, Soleus, Plantar Fascia | F37: Tibialis Posterior, Peroneals | H37: Specialized | I37: Achilles — reactive overload if volume too high; Plantar Fascia — stress at push-off; Ankle — instability | J37: Minimal knee bend — all ankle; quick ground contact; builds ankle stiffness for running economy | K37: Jump rope (double-under rhythm sim); Rebounding on mini trampoline; 🏠 No equipment needed; any flat surface | L37: EX025 — Single-Leg Calf Raise (Loaded); EX027 — Tibialis Raise | M37: Achilles, Plantar Fascia, Ankle | N37: EX008 — Broad Jump | O37: EX026 — Seated Calf Raise | P37: =COUNTIF('Sport-Exercise Map'!A:A,A37)
A38: EX036 | B38: Running Bounds (Exaggerated Stride) | C38: Plyometric | D38: Single-Leg, Locomotion, Hip-Ext | E38: Glutes, Hamstrings, Hip Flexors | F38: Core, Calves | H38: Common | I38: Hip Flexor — at peak extension; Hamstring — at landing position if tight; Achilles — push-off demand | J38: Exaggerate flight phase; powerful push-off and high knee drive; builds stride power for uphills | K38: Uphill bounding (terrain sub); Resist band bounds (added resistance); 🏠 No equipment needed; hallway, parking lot, or park grass | L38: EX048 — Hill Repeats; EX031 — Kettlebell Swing (Two-Hand) | M38: Hip Flexor, Hamstring, Achilles | O38: EX034 — Lateral Bound | P38: =COUNTIF('Sport-Exercise Map'!A:A,A38)
A39: EX037 | B39: Wall Sit | C39: Isometric | D39: Squat | E39: Quadriceps (VMO) | F39: Glutes, Core | H39: Common | I39: Knee — patellar tendon stress at 90° hold; Lumbar — if back loses wall contact | J39: Thighs parallel to floor; progress by time then add vest or plate on thighs; excellent hotel exercise | K39: 🏠 Any wall; hotel room wall; add backpack on thighs for progression | L39: EX038 — Split Squat ISO Hold; EX002 — Goblet Squat held at depth | M39: Knee, Lumbar | N39: EX002 — Goblet Squat (DB/KB) | P39: =COUNTIF('Sport-Exercise Map'!A:A,A39)
A40: EX038 | B40: Split Squat ISO Hold | C40: Isometric | D40: Single-Leg, Squat | E40: Quadriceps, Glutes, Hip Flexors | F40: Core, Hip Stabilisers | G40: Dumbbell, Kettlebell | H40: Specialized | I40: Knee — anterior pain if front shin angles forward; Hip Flexor — stretch discomfort at bottom | J40: Hold bottom position of Bulgarian or reverse lunge; builds end-range stability for trail and climbing terrain | K40: Barbell split squat hold at bottom; Loaded sandbag version; 🏠 Chair seat for rear foot elevation; bed edge; no equipment for floor version | L40: EX037 — Wall Sit; EX043 — Single-Leg Balance Hold | M40: Knee, Hip Flexor | N40: EX021 — Bulgarian Split Squat (DB) | P40: =COUNTIF('Sport-Exercise Map'!A:A,A40)
...

Sheet Sport-Exercise Map
A1: ADVENTURE RACING — SPORT-EXERCISE CROSS REFERENCE
A2: Exercise ID | B2: Exercise Name | C2: Exercise Type | D2: Sport | E2: Sport Relevance Note | F2: Priority
A3: EX001 | B3: Back Squat (Barbell) | C3: Strength | D3: Trail Running | E3: Primary lower body strength builder; powers uphill drive and controls eccentric descent load under pack | F3: High
A4: EX002 | B4: Goblet Squat (DB/KB) | C4: Strength | D4: Trail Running | E4: Hotel substitute for back squat; same sport carryover with less equipment | F4: High
A5: EX003 | B5: Romanian Deadlift (Barbell) | C5: Strength | D5: Trail Running | E5: Hamstring and glute loading for push-off power and descent control; posterior chain base | F5: High
A6: EX004 | B6: Single-Leg RDL (DB) | C6: Strength | D6: Trail Running | E6: Unilateral posterior chain; directly mirrors single-leg braking mechanics on trail descents | F6: High
A7: EX007 | B7: Box Jump | C7: Plyometric | D7: Trail Running | E7: Explosive hip extension for steep uphill transitions and obstacle clearance | F7: High
A8: EX008 | B8: Broad Jump | C8: Plyometric | D8: Trail Running | E8: Horizontal power output; stream crossings, obstacle hops; also a field test metric | F8: High
A9: EX009 | B9: Farmer Carry | C9: Loaded Carry | D9: Trail Running | E9: Pack carry simulation; builds grip, trap, and core endurance under sustained load | F9: Medium
A10: EX010 | B10: Rucking (Weighted Hike) | C10: Loaded Carry | D10: Trail Running | E10: Direct race sim for foot legs; primary training modality for AR pack adaptation | F10: Critical
A11: EX011 | B11: Pallof Press (Band/Cable) | C11: Isometric | D11: Trail Running | E11: Core anti-rotation under load; controls lateral trunk sway with heavy pack | F11: Medium
A12: EX012 | B12: Copenhagen Plank | C12: Isometric | D12: Trail Running | E12: Groin and adductor strength for lateral terrain demands and hip stability under fatigue | F12: High
A13: EX013 | B13: Hip Circle (Band) | C13: Activation / Primer | D13: Trail Running | E13: Pre-run glute activation; ensures glutes fire before demand is placed on the kinetic chain | F13: High
... A1010: EX230 | B1010: Conventional Deadlift (Barbell) | C1010: Strength | D1010: Marathon | E1010: Posterior chain strength base; the hip hinge pattern underlies every running push-off across 26.2 miles | F1010: High

Sheet Sport Summary
A1: EXERCISES BY SPORT — QUICK REFERENCE
A2: Trail Running | D2: Orienteering | G2: Mountain Biking | J2: Packrafting | M2: Rock Climbing | P2: Hiking | S2: Swimming | V2: Rappelling / Abseiling | Y2: Fixed Rope / Via Ferrata | AA2: XC / AR Cycling | AD2: Mountaineering | AG2: Snowshoeing | AI2: Kayaking | AL2: Canoeing | AO2: Paddle Rafting | AQ2: SkiMo | AS2: Triathlon | AU2: Marathon | AX2: Ultramarathon | AZ2: Road Cycling | BC2: Gravel Cycling | BF2: Bikepacking | BH2: Fencing | BK2: Obstacle Course Racing | BN2: Modern Pentathlon | BP2: Run-Bike-Run Duathlon | BS2: SwimRun | BU2: Rowing | BX2: XC Skiing | CA2: SUP | CC2: Long Distance Paddle Racing | CF2: Long Distance Orienteering | CI2: Multi-Sport Race | CK2: Mountain Running / Sky Running | CN2: Fell Running | CP2: General Conditioning
A3: Priority | B3: Exercise | D3: Priority | E3: Exercise | G3: Priority | H3: Exercise | J3: Priority | K3: Exercise | M3: Priority | N3: Exercise | P3: Priority | Q3: Exercise | S3: Priority | T3: Exercise | V3: Priority | W3: Exercise | Y3: Priority | Z3: Exercise | AA3: Priority | AB3: Exercise | AD3: Priority | AE3: Exercise | AG3: Priority | AH3: Exercise | AI3: Priority | AJ3: Exercise | AL3: Priority | AM3: Exercise | AO3: Priority | AP3: Exercise | AQ3: Priority | AR3: Exercise | AS3: Priority | AT3: Exercise | AU3: Priority | AV3: Exercise | AX3: Priority | AY3: Exercise | AZ3: Priority | BA3: Exercise | BC3: Priority | BD3: Exercise | BF3: Priority | BG3: Exercise | BH3: Priority | BI3: Exercise | BK3: Priority | BL3: Exercise | BN3: Priority | BO3: Exercise | BP3: Priority | BQ3: Exercise | BS3: Priority | BT3: Exercise | BU3: Priority | BV3: Exercise | BX3: Priority | BY3: Exercise | CA3: Priority | CB3: Exercise | CC3: Priority | CD3: Exercise | CF3: Priority | CG3: Exercise | CI3: Priority | CJ3: Exercise | CK3: Priority | CL3: Exercise | CN3: Priority | CO3: Exercise | CP3: Priority | CQ3: Exercise
A4: Critical | B4: EX010 — Rucking (Weighted Hike) | D4: Critical | E4: EX053 — Agility Ladder Drill | G4: Critical | H4: EX073 — Threshold Intervals (Bike) | J4: Critical | K4: EX090 — Paddling Ergometer Session | M4: Critical | N4: EX005 — Dead Hang | P4: Critical | Q4: EX010 — Rucking (Weighted Hike) | S4: Critical | T4: EX127 — Band Swimming Shoulder Prehab (Y-T-W-L) | V4: Critical | W4: EX130 — Rappel Device Operation Drill | Y4: Critical | Z4: EX134 — Ascender / Jumar Technique Drill | AA4: Critical | AB4: EX144 — Hike-a-Bike Carry Drill | AD4: Critical | AE4: EX148 — Crampon Walking Technique | AG4: Critical | AH4: EX153 — Snowshoe Gait Technique | AI4: Critical | AJ4: EX158 — Whitewater Line Reading | AL4: Critical | AM4: EX156 — Sweep Stroke Technique Drill | AO4: Critical | AP4: EX158 — Whitewater Line Reading | AQ4: Critical | AR4: EX168 — Skinning Uphill Technique | AS4: Critical | AT4: EX174 — Aero / TT Position Hold | AU4: Critical | AV4: EX178 — Tempo Run (Flat / Road) | AX4: Critical | AY4: EX180 — Walk-Run Interval Method (Ultra Pacing) | AZ4: Critical | BA4: EX184 — Road Cycling Descending Technique | BC4: Critical | BD4: EX185 — Climb Pacing & Cadence Management | BF4: Critical | BG4: EX185 — Climb Pacing & Cadence Management | BH4: Critical | BI4: EX190 — En Garde Position Hold | BK4: Critical | BL4: EX195 — Rope Climb | BN4: Critical | BO4: EX190 — En Garde Position Hold | BP4: Critical | BQ4: EX197 — Double Brick / Run-Bike-Run Pacing Drill | BS4: Critical | BT4: EX198 — Running in Wetsuit (SwimRun) | BU4: Critical | BV4: EX200 — Rowing Drive Sequence Drill | BX4: Critical | BY4: EX205 — Classic Diagonal Stride Technique | CA4: Critical | CB4: EX209 — SUP Forward Stroke Technique | CC4: Critical | CD4: EX160 — Seated Paddling Position Endurance | CF4: Critical | CG4: EX057 — Map Navigation Run | CI4: Critical | CJ4: EX175 — Brick Run Drill (Bike-to-Run Transition) | CK4: Critical | CL4: EX212 — Scrambling Technique (Moving Terrain) | CN4: Critical | CO4: EX214 — Fell Descent Technique (Steep Grass, Bog, Heather) | CP4: Critical | CQ4: EX216 — Plank (Front)
A5: Critical | B5: EX021 — Bulgarian Split Squat (DB) | D5: Critical | E5: EX056 — Reactive Direction Change Drill | G5: Critical | H5: EX074 — VO2 Max Intervals (Bike) | J5: Critical | K5: EX091 — Forward Stroke Technique Drill | M5: Critical | N5: EX006 — Pull-Up (BW) | P5: Critical | Q5: EX120 — Sustained LISS (Hiking Pace) | S5: Critical | T5: EX082 — External Rotation (Band / Cable) | V5: Critical | W5: EX131 — Wall Walk Descent Technique | Y5: Critical | Z5: EX135 — Via Ferrata Progressive Clip Drill | AA5: Critical | AB5: EX145 — Loaded Bike Low-Speed Balance Drill | AD5: Critical | AE5: EX149 — Ice Axe Self-Arrest | AG5: Critical | AH5: EX154 — Plunge Step Descent (Snowshoe) | AI5: Critical | AJ5: EX159 — Wet Exit & Re-entry (Kayak) | AL5: Critical | AM5: EX157 — Draw Stroke & Pry Technique | AO5: Critical | AP5: EX164 — High-Side Command Response Drill | AQ5: Critical | AR5: EX169 — Ski Kick-Turn on Slope | AS5: Critical | AT5: EX175 — Brick Run Drill (Bike-to-Run Transition) | AU5: Critical | AV5: EX179 — Marathon Pace Run | AX5: Critical | AY5: EX181 — On-the-Run Fueling Drill | AZ5: Critical | BA5: EX185 — Climb Pacing & Cadence Management | BC5: Critical | BD5: EX187 — Gravel Surface Reading & Line Selection | BF5: Critical | BG5: EX188 — Loaded Touring / Bikepacking Bike Handling | BH5: Critical | BI5: EX191 — Fencing Lunge & Recovery | BK5: Critical | BL5: EX196 — Obstacle Vault & Wall Traversal | BN5: Critical | BO5: EX191 — Fencing Lunge & Recovery | BP5: Critical | BQ5: EX175 — Brick Run Drill (Bike-to-Run Transition) | BS5: Critical | BT5: EX199 — SwimRun Water Entry & Exit Technique | BU5: Critical | BV5: EX201 — Catch Position Hold (Rowing) | BX5: Critical | BY5: EX206 — Skate Skiing V1 & V2 Technique | CA5: Critical | CB5: EX210 — SUP Standing Balance & Stability Drill | CC5: Critical | CD5: EX091 — Forward Stroke Technique Drill | CF5: Critical | CG5: EX058 — Compass Bearing Walk / Run | CI5: Critical | CJ5: EX176 — Triathlon Transition Practice (T1 & T2) | CK5: Critical | CL5: EX213 — Scree Running Descent Technique | CN5: Critical | CO5: EX215 — Extreme Gradient Uphill Pacing (VK / Sky Technique) | CP5: Critical | CQ5: EX217 — Dead Bug
A6: Critical | B6: EX025 — Single-Leg Calf Raise (Loaded) | D6: Critical | E6: EX057 — Map Navigation Run | G6: Critical | H6: EX075 — Sweet Spot Training (Bike) | J6: Critical | K6: EX082 — External Rotation (Band / Cable) | M6: Critical | N6: EX100 — Hangboard Half-Crimp Hold | P6: Critical | Q6: EX021 — Bulgarian Split Squat (DB) | S6: High | T6: EX126 — Freestyle Pull (With Buoy) | V6: Critical | W6: EX132 — Anchor Setup & Inspection | Y6: Critical | Z6: EX136 — Fixed Rope Body Position & Rest Drill | AA6: Critical | AB6: EX146 — Navigation While Cycling Drill | AD6: Critical | AE6: EX150 — Rest Step Technique | AG6: Critical | AH6: EX010 — Rucking (Weighted Hike) | AI6: Critical | AJ6: EX166 — Ferry & Eddy Turn Technique | AL6: Critical | AM6: EX158 — Whitewater Line Reading | AO6: Critical | AP6: EX165 — Raft Paddle Synchronisation & Power Phase | AQ6: Critical | AR6: EX170 — SkiMo Race Transition Drill | AS6: Critical | AT6: EX176 — Triathlon Transition Practice (T1 & T2) | AU6: Critical | AV6: EX181 — On-the-Run Fueling Drill | AX6: Critical | AY6: EX182 — Night Running & Low-Light Technique | AZ6: Critical | BA6: EX189 — Road & Gravel Paceline Technique | BC6: Critical | BD6: EX147 — Loose Surface Threshold Braking | BF6: Critical | BG6: EX144 — Hike-a-Bike Carry Drill | BH6: Critical | BI6: EX192 — Fencing Advance-Retreat Footwork Drill | BK6: Critical | BL6: EX006 — Pull-Up (BW) | BN6: Critical | BO6: EX192 — Fencing Advance-Retreat Footwork Drill | BP6: Critical | BQ6: EX073 — Threshold Intervals (Bike) | BS6: Critical | BT6: EX126 — Freestyle Pull (With Buoy) | BU6: Critical | BV6: EX203 — Rowing Erg Interval Session | BX6: Critical | BY6: EX207 — Double Pole Technique (XC Skiing) | CA6: Critical | CB6: EX016 — Thoracic Rotation Drill | CC6: Critical | CD6: EX090 — Paddling Ergometer Session | CF6: Critical | CG6: EX059 — Neck Isometric Hold (Map Reading Position) | CI6: Critical | CJ6: EX197 — Double Brick / Run-Bike-Run Pacing Drill | CK6: Critical | CL6: EX215 — Extreme Gradient Uphill Pacing (VK / Sky Technique) | CN6: Critical | CO6: EX052 — Downhill Running Technique Drill | CP6: Critical | CQ6: EX218 — Bird-Dog
A7: Critical | B7: EX048 — Hill Repeats | D7: Critical | E7: EX058 — Compass Bearing Walk / Run | G7: Critical | H7: EX067 — MTB Attack Position Hold | J7: Critical | K7: EX092 — Bracing Stroke Drill | M7: Critical | N7: EX101 — Hangboard Open-Hand Hold | P7: Critical | Q7: EX024 — Step-Up High Box (Loaded) | S7: High | T7: EX128 — Kicking Drill (Flutter / Frog) | V7: High | W7: EX133 — Brake Hand Squeeze Hold | Y7: Critical | Z7: EX005 — Dead Hang | AA7: Critical | AB7: EX073 — Threshold Intervals (Bike) | AD7: Critical | AE7: EX010 — Rucking (Weighted Hike) | AG7: Critical | AH7: EX120 — Sustained LISS (Hiking Pace) | AI7: Critical | AJ7: EX090 — Paddling Ergometer Session | AL7: Critical | AM7: EX161 — J-Stroke Technique | AO7: High | AP7: EX160 — Seated Paddling Position Endurance | AQ7: Critical | AR7: EX171 — Touring Ski Descent Technique | AS7: Critical | AT7: EX126 — Freestyle Pull (With Buoy) | AU7: Critical | AV7: EX025 — Single-Leg Calf Raise (Loaded) | AX7: Critical | AY7: EX183 — Running with Poles (Trail / Ultra) | AZ7: Critical | BA7: EX073 — Threshold Intervals (Bike) | BC7: Critical | BD7: EX073 — Threshold Intervals (Bike) | BF7: Critical | BG7: EX145 — Loaded Bike Low-Speed Balance Drill | BH7: Critical | BI7: EX021 — Bulgarian Split Squat (DB) | BK7: Critical | BL7: EX005 — Dead Hang | BN7: Critical | BO7: EX194 — Laser-Run Drill (Run-to-Shoot Transition) | BP7: Critical | BQ7: EX075 — Sweet Spot Training (Bike) | BS7: Critical | BT7: EX127 — Band Swimming Shoulder Prehab (Y-T-W-L) | BU7: Critical | BV7: EX204 — On-Water Boat Balance Drill | BX7: Critical | BY7: EX019 — Barbell Hip Thrust | CA7: High | CB7: EX211 — SUP Downwind & Wave Reading | CC7: Critical | CD7: EX161 — J-Stroke Technique | CF7: Critical | CG7: EX010 — Rucking (Weighted Hike) | CI7: Critical | CJ7: EX021 — Bulgarian Split Squat (DB) | CK7: Critical | CL7: EX052 — Downhill Running Technique Drill | CN7: Critical | CO7: EX021 — Bulgarian Split Squat (DB) | CP7: Critical | CQ7: EX219 — Side Plank
A8: Critical | B8: EX051 — Uphill Running Technique Drill | D8: High | E8: EX010 — Rucking (Weighted Hike) | G8: Critical | H8: EX070 — Single-Leg Cycling Drill (Trainer) | J8: Critical | K8: EX016 — Thoracic Rotation Drill | M8: Critical | N8: EX105 — Finger Extension (Band) | P8: Critical | Q8: EX117 — Loaded Step-Down (Eccentric Box) | S8: High | T8: EX129 — Swim-Specific Rotational Core (Dry Land) | V8: High | W8: EX005 — Dead Hang | Y8: Critical | Z8: EX006 — Pull-Up (BW) | AA8: Critical | AB8: EX075 — Sweet Spot Training (Bike) | AD8: Critical | AE8: EX120 — Sustained LISS (Hiking Pace) | AG8: High | AH8: EX155 — Snowshoe Sidehill Traverse & Kickturn | AI8: Critical | AJ8: EX091 — Forward Stroke Technique Drill | AL8: Critical | AM8: EX162 — Tandem Canoe Coordination Drill | AO8: High | AP8: EX157 — Draw Stroke & Pry Technique | AQ8: Critical | AR8: EX173 — Tuck Position Isometric Hold | AS8: Critical | AT8: EX127 — Band Swimming Shoulder Prehab (Y-T-W-L) | AU8: Critical | AV8: EX021 — Bulgarian Split Squat (DB) | AX8: Critical | AY8: EX021 — Bulgarian Split Squat (DB) | AZ8: Critical | BA8: EX075 — Sweet Spot Training (Bike) | BC8: Critical | BD8: EX075 — Sweet Spot Training (Bike) | BF8: Critical | BG8: EX075 — Sweet Spot Training (Bike) | BH8: Critical | BI8: EX056 — Reactive Direction Change Drill | BK8: Critical | BL8: EX009 — Farmer Carry | BN8: Critical | BO8: EX193 — Shooting Breath Control & Stance | BP8: Critical | BQ8: EX178 — Tempo Run (Flat / Road) | BS8: Critical | BT8: EX141 — Wetsuit Swimming Technique | BU8: Critical | BV8: EX001 — Back Squat (Barbell) | BX8: Critical | BY8: EX023 — Lateral Lunge (DB or BW) | CA8: High | CB8: EX090 — Paddling Ergometer Session | CC8: Critical | CD8: EX162 — Tandem Canoe Coordination Drill | CF8: Critical | CG8: EX120 — Sustained LISS (Hiking Pace) | CI8: Critical | CJ8: EX076 — Couch Stretch (Cyclist Hip Flexor) | CK8: Critical | CL8: EX051 — Uphill Running Technique Drill | CN8: Critical | CO8: EX117 — Loaded Step-Down (Eccentric Box) | CP8: Critical | CQ8: EX220 — Superman / Back Extension (BW)
A9: Critical | B9: EX052 — Downhill Running Technique Drill | D9: High | E9: EX008 — Broad Jump | G9: Critical | H9: EX076 — Couch Stretch (Cyclist Hip Flexor) | J9: High | K9: EX005 — Dead Hang | M9: Critical | N9: EX106 — Lock-Off Hold (90°, 120°) | P9: Critical | Q9: EX119 — Weighted Step-Up (High Box, Heavy Load) | S9: High | T9: EX006 — Pull-Up (BW) | V9: High | W9: EX006 — Pull-Up (BW) | Y9: High | Z9: EX019 — Barbell Hip Thrust | AA9: Critical | AB9: EX070 — Single-Leg Cycling Drill (Trainer) | AD9: Critical | AE9: EX119 — Weighted Step-Up (High Box, Heavy Load) | AG9: High | AH9: EX021 — Bulgarian Split Squat (DB) | AI9: Critical | AJ9: EX082 — External Rotation (Band / Cable) | AL9: Critical | AM9: EX163 — Canoe Portage Yoke Carry | AO9: High | AP9: EX156 — Sweep Stroke Technique Drill | AQ9: Critical | AR9: EX148 — Crampon Walking Technique | AS9: Critical | AT9: EX140 — Open Water Sighting Drill | AU9: Critical | AV9: EX035 — Ankle Hops / Pogo Jumps | AX9: Critical | AY9: EX020 — Nordic Hamstring Curl | AZ9: Critical | BA9: EX069 — Neck Extension Strengthening | BC9: Critical | BD9: EX076 — Couch Stretch (Cyclist Hip Flexor) | BF9: Critical | BG9: EX120 — Sustained LISS (Hiking Pace) | BH9: Critical | BI9: EX046 — Hip Flexor Lunge Stretch | BK9: High | BL9: EX078 — Single-Arm DB Row | BN9: Critical | BO9: EX126 — Freestyle Pull (With Buoy) | BP9: Critical | BQ9: EX021 — Bulgarian Split Squat (DB) | BS9: Critical | BT9: EX140 — Open Water Sighting Drill | BU9: Critical | BV9: EX089 — Hollow Body Hold | BX9: Critical | BY9: EX017 — Lateral Band Walk | CA9: High | CB9: EX087 — Cable High-to-Low Chop | CC9: Critical | CD9: EX095 — Portage Carry Simulation | CF9: Critical | CG9: EX180 — Walk-Run Interval Method (Ultra Pacing) | CI9: High | CJ9: EX178 — Tempo Run (Flat / Road) | CK9: Critical | CL9: EX048 — Hill Repeats | CN9: Critical | CO9: EX020 — Nordic Hamstring Curl | CP9: Critical | CQ9: EX228 — Push-Up (Bodyweight)
A10: High | B10: EX001 — Back Squat (Barbell) | D10: High | E10: EX012 — Copenhagen Plank | G10: High | H10: EX001 — Back Squat (Barbell) | J10: High | K10: EX006 — Pull-Up (BW) | M10: Critical | N10: EX109 — Scapular Pull-Up | P10: Critical | Q10: EX121 — Trekking Pole Technique (Descent Braking) | S10: High | T10: EX080 — Lat Pulldown (Wide Grip) | V10: High | W10: EX043 — Single-Leg Balance Hold | Y10: High | Z10: EX021 — Bulgarian Split Squat (DB) | AA10: Critical | AB10: EX069 — Neck Extension Strengthening | AD10: High | AE10: EX151 — Rope Team Travel Drill | AG10: High | AH10: EX119 — Weighted Step-Up (High Box, Heavy Load) | AI10: Critical | AJ10: EX092 — Bracing Stroke Drill (High and Low) | AL10: Critical | AM10: EX166 — Ferry & Eddy Turn Technique | AO10: High | AP10: EX085 — Med Ball Rotational Throw (Wall) | AQ10: Critical | AR10: EX149 — Ice Axe Self-Arrest | AS10: Critical | AT10: EX082 — External Rotation (Band / Cable) | AU10: Critical | AV10: EX017 — Lateral Band Walk | AX10: Critical | AY10: EX025 — Single-Leg Calf Raise (Loaded) | AZ10: Critical | BA10: EX076 — Couch Stretch (Cyclist Hip Flexor) | BC10: Critical | BD10: EX069 — Neck Extension Strengthening | BF10: Critical | BG10: EX069 — Neck Extension Strengthening | BH10: High | BI10: EX022 — Reverse Lunge (DB or BW) | BK10: High | BL10: EX080 — Lat Pulldown (Wide Grip) | BN10: Critical | BO10: EX127 — Band Swimming Shoulder Prehab (Y-T-W-L) | BP10: Critical | BQ10: EX076 — Couch Stretch (Cyclist Hip Flexor) | BS10: Critical | BT10: EX082 — External Rotation (Band / Cable) | BU10: Critical | BV10: EX082 — External Rotation (Band / Cable) | BX10: Critical | BY10: EX207 — Double Pole Technique (XC Skiing) | CA10: High | CB10: EX085 — Med Ball Rotational Throw (Wall) | CC10: Critical | CD10: EX163 — Canoe Portage Yoke Carry | CF10: Critical | CG10: EX182 — Night Running & Low-Light Technique | CI10: High | CJ10: EX048 — Hill Repeats | CK10: Critical | CL10: EX021 — Bulgarian Split Squat (DB) | CN10: Critical | CO10: EX043 — Single-Leg Balance Hold | CP10: Critical | CQ10: EX230 — Conventional Deadlift (Barbell)
A11: High | B11: EX002 — Goblet Squat (DB/KB) | D11: High | E11: EX017 — Lateral Band Walk | G11: High | H11: EX002 — Goblet Squat (DB/KB) | J11: High | K11: EX078 — Single-Arm DB Row | M11: Critical | N11: EX110 — Antagonist Push-Up (Fist / Flat) | P11: Critical | Q11: EX123 — Pack Fit Optimization Drill | S11: High | T11: EX078 — Single-Arm DB Row | V11: High | W11: EX102 — Pinch Grip (Plate / Block) | Y11: High | Z11: EX024 — Step-Up High Box (Loaded) | AA11: Critical | AB11: EX076 — Couch Stretch (Cyclist Hip Flexor) | AD11: High | AE11: EX152 — Post-Hole Recovery Gait | AG11: High | AH11: EX017 — Lateral Band Walk | AI11: Critical | AJ11: EX093 — Eskimo Roll Practice | AL11: Critical | AM11: EX090 — Paddling Ergometer Session | AO11: High | AP11: EX087 — Cable High-to-Low Chop | AQ11: Critical | AR11: EX048 — Hill Repeats | AS11: Critical | AT11: EX073 — Threshold Intervals (Bike) | AU11: Critical | AV11: EX046 — Hip Flexor Lunge Stretch | AX11: Critical | AY11: EX117 — Loaded Step-Down (Eccentric Box) | AZ11: High | BA11: EX186 — High Cadence Spin Drill | BC11: Critical | BD11: EX068 — Wrist Pronation / Supination (DB) | BF11: Critical | BG11: EX076 — Couch Stretch (Cyclist Hip Flexor) | BH11: High | BI11: EX038 — Split Squat ISO Hold | BK11: High | BL11: EX089 — Hollow Body Hold | BN11: Critical | BO11: EX082 — External Rotation (Band / Cable) | BP11: Critical | BQ11: EX046 — Hip Flexor Lunge Stretch | BS11: Critical | BT11: EX043 — Single-Leg Balance Hold | BU11: Critical | BV11: EX047 — Calf / Achilles Wall Stretch | BX11: Critical | BY11: EX048 — Hill Repeats | CA11: High | CB11: EX086 — Landmine Rotation | CC11: Critical | CD11: EX082 — External Rotation (Band / Cable) | CF11: Critical | CG11: EX181 — On-the-Run Fueling Drill | CI11: High | CJ11: EX049 — Strides (Flying Sprints) | CK11: Critical | CL11: EX117 — Loaded Step-Down (Eccentric Box) | CN11: Critical | CO11: EX035 — Ankle Hops / Pogo Jumps | CP11: Critical | CQ11: EX243 — Suitcase Carry
A12: High | B12: EX003 — Romanian Deadlift (Barbell) | D12: High | E12: EX034 — Lateral Bound | G12: High | H12: EX019 — Barbell Hip Thrust | J12: High | K12: EX079 — Seated Cable Row (Narrow Grip) | M12: Critical | N12: EX112 — Belay Simulation (Device Practice) | P12: Critical | Q12: EX124 — Power Hiking Technique | S12: High | T12: EX081 — Band Face Pull | V12: High | W12: EX106 — Lock-Off Hold (90°, 120°) | Y12: High | Z12: EX043 — Single-Leg Balance Hold | AA12: High | AB12: EX147 — Loose Surface Threshold Braking | AD12: High | AE12: EX024 — Step-Up High Box (Loaded) | AG12: High | AH12: EX023 — Lateral Lunge (DB or BW) | AI12: Critical | AJ12: EX016 — Thoracic Rotation Drill | AL12: Critical | AM12: EX091 — Forward Stroke Technique Drill | AO12: High | AP12: EX078 — Single-Arm DB Row | AQ12: Critical | AR12: EX021 — Bulgarian Split Squat (DB) | AS12: Critical | AT12: EX075 — Sweet Spot Training (Bike) | AU12: Critical | AV12: EX047 — Calf / Achilles Wall Stretch | AX12: Critical | AY12: EX120 — Sustained LISS (Hiking Pace) | AZ12: High | BA12: EX074 — VO2 Max Intervals (Bike) | BC12: High | BD12: EX184 — Road Cycling Descending Technique | BF12: Critical | BG12: EX046 — Hip Flexor Lunge Stretch | BH12: High | BI12: EX023 — Lateral Lunge (DB or BW) | BK12: High | BL12: EX110 — Antagonist Push-Up (Fist / Flat) | BN12: Critical | BO12: EX178 — Tempo Run (Flat / Road) | BP12: High | BQ12: EX176 — Triathlon Transition Practice (T1 & T2) | BS12: High | BT12: EX142 — Bilateral Breathing Drill | BU12: Critical | BV12: EX045 — Ankle Mobility Drill (Wall) | BX12: High | BY12: EX208 — Herringbone & Steep Uphill Technique | CA12: High | CB12: EX089 — Hollow Body Hold | CC12: Critical | CD12: EX081 — Band Face Pull | CF12: Critical | CG12: EX124 — Power Hiking Technique | CI12: High | CJ12: EX025 — Single-Leg Calf Raise (Loaded) | CK12: Critical | CL12: EX020 — Nordic Hamstring Curl | CN12: Critical | CO12: EX027 — Tibialis Raise (Wall or Machine) | CP12: High | CQ12: EX221 — Mountain Climber
A13: High | B13: EX004 — Single-Leg RDL (DB) | D13: High | E13: EX048 — Hill Repeats | G13: High | H13: EX031 — Kettlebell Swing (Two-Hand) | J13: High | K13: EX080 — Lat Pulldown (Wide Grip) | M13: Critical | N13: EX113 — Movement on Route (Top-Rope / Lead) | P13: High | Q13: EX001 — Back Squat (Barbell) | S13: High | T13: EX083 — Serratus Punch | V13: High | W13: EX112 — Belay Simulation (Device Practice) | Y13: High | Z13: EX106 — Lock-Off Hold (90°, 120°) | AA13: High | AB13: EX074 — VO2 Max Intervals (Bike) | AD13: High | AE13: EX021 — Bulgarian Split Squat (DB) | AG13: High | AH13: EX040 — Clamshell (Band) | AI13: High | AJ13: EX156 — Sweep Stroke Technique Drill | AL13: Critical | AM13: EX087 — Cable High-to-Low Chop | AO13: High | AP13: EX089 — Hollow Body Hold | AQ13: Critical | AR13: EX017 — Lateral Band Walk | AS13: Critical | AT13: EX076 — Couch Stretch (Cyclist Hip Flexor) | AU13: Critical | AV13: EX018 — Foam Roll (IT Band / Quads / Lats) | AX13: Critical | AY13: EX124 — Power Hiking Technique | AZ13: High | BA13: EX070 — Single-Leg Cycling Drill (Trainer) | BC13: High | BD13: EX186 — High Cadence Spin Drill | BF13: High | BG13: EX186 — High Cadence Spin Drill | BH13: High | BI13: EX037 — Wall Sit | BK13: High | BL13: EX104 — Rice Bucket Drill | BN13: Critical | BO13: EX021 — Bulgarian Split Squat (DB) | BP13: High | BQ13: EX074 — VO2 Max Intervals (Bike) | BS13: High | BT13: EX081 — Band Face Pull | BU13: High | BV13: EX202 — Blade Extraction & Feathering Drill | BX13: High | BY13: EX021 — Bulgarian Split Squat (DB) | CA13: High | CB13: EX011 — Pallof Press (Band/Cable) | CC13: Critical | CD13: EX016 — Thoracic Rotation Drill | CF13: Critical | CG13: EX123 — Pack Fit Optimization Drill | CI13: High | CJ13: EX017 — Lateral Band Walk | CK13: Critical | CL13: EX033 — Depth Drop (Eccentric Landing Practice) | CN13: Critical | CO13: EX048 — Hill Repeats | CP13: High | CQ13: EX222 — Ab Wheel Rollout
A14: High | B14: EX007 — Box Jump | D14: High | E14: EX014 — World's Greatest Stretch | G14: High | H14: EX060 — Single-Leg Press (Machine) | J14: High | K14: EX083 — Serratus Punch | M14: Critical | N14: EX089 — Hollow Body Hold | P14: High | Q14: EX003 — Romanian Deadlift (Barbell) | S14: High | T14: EX016 — Thoracic Rotation Drill | V14: Medium | W14: EX009 — Farmer Carry | Y14: Medium | Z14: EX009 — Farmer Carry | AA14: High | AB14: EX019 — Barbell Hip Thrust | AD14: High | AE14: EX001 — Back Squat (Barbell) | AG14: High | AH14: EX041 — Monster Walk (Band) | AI14: High | AJ14: EX157 — Draw Stroke & Pry Technique | AL14: Critical | AM14: EX078 — Single-Arm DB Row | AO14: High | AP14: EX082 — External Rotation (Band / Cable) | AQ14: Critical | AR14: EX046 — Hip Flexor Lunge Stretch | AS14: Critical | AT14: EX016 — Thoracic Rotation Drill | AU14: High | AV14: EX026 — Seated Calf Raise | AX14: Critical | AY14: EX017 — Lateral Band Walk | AZ14: High | BA14: EX019 — Barbell Hip Thrust | BC14: High | BD14: EX189 — Road & Gravel Paceline Technique | BF14: High | BG14: EX187 — Gravel Surface Reading & Line Selection | BH14: High | BI14: EX025 — Single-Leg Calf Raise (Loaded) | BK14: High | BL14: EX102 — Pinch Grip (Plate / Block) | BN14: Critical | BO14: EX046 — Hip Flexor Lunge Stretch | BP14: High | BQ14: EX070 — Single-Leg Cycling Drill (Trainer) | BS14: High | BT14: EX016 — Thoracic Rotation Drill | BU14: High | BV14: EX006 — Pull-Up (BW) | BX14: High | BY14: EX040 — Clamshell (Band) | CA14: High | CB14: EX043 — Single-Leg Balance Hold | CC14: Critical | CD14: EX005 — Dead Hang | CF14: Critical | CG14: EX021 — Bulgarian Split Squat (DB) | CI14: High | CJ14: EX073 — Threshold Intervals (Bike) | CK14: Critical | CL14: EX043 — Single-Leg Balance Hold | CN14: Critical | CO14: EX051 — Uphill Running Technique Drill | CP14: High | CQ14: EX223 — Hanging Knee Raise / Toes-to-Bar
... A16: High | B16: EX012 — Copenhagen Plank | D16: High | E16: EX054 — T-Drill / 5-10-5 Cone Drill | G16: High | H16: EX062 — Banded Hip Flexion (Standing) | J16: High | K16: EX086 — Landmine Rotation | M16: High | N16: EX103 — Wrist Roller | P16: High | Q16: EX019 — Barbell Hip Thrust | S16: High | T16: EX065 — Scapular Wall Slide | V16: Medium | W16: EX011 — Pallof Press (Band/Cable) | Y16: Medium | Z16: EX104 — Rice Bucket Drill | AA16: High | AB16: EX021 — Bulgarian Split Squat (DB) | AD16: High | AE16: EX025 — Single-Leg Calf Raise (Loaded) | AG16: High | AH16: EX048 — Hill Repeats | AI16: High | AJ16: EX167 — Ocean / Surf Zone Entry & Exit | AL16: Critical | AM16: EX082 — External Rotation (Band / Cable) | AO16: High | AP16: EX016 — Thoracic Rotation Drill | AQ16: High | AR16: EX150 — Rest Step Technique | AS16: Critical | AT16: EX046 — Hip Flexor Lunge Stretch | AU16: High | AV16: EX020 — Nordic Hamstring Curl | AX16: Critical | AY16: EX047 — Calf / Achilles Wall Stretch | AZ16: High | BA16: EX021 — Bulgarian Split Squat (DB) | BC16: High | BD16: EX074 — VO2 Max Intervals (Bike) | BF16: High | BG16: EX009 — Farmer Carry | BH16: High | BI16: EX001 — Back Squat (Barbell) | BK16: High | BL16: EX095 — Portage Carry Simulation | BN16: High | BO16: EX195 — Rope Climb | BP16: High | BQ16: EX179 — Marathon Pace Run | BS16: High | BT16: EX178 — Tempo Run (Flat / Road) | BU16: High | BV16: EX080 — Lat Pulldown (Wide Grip) | BX16: High | BY16: EX012 — Copenhagen Plank | CA16: High | CB16: EX082 — External Rotation (Band / Cable) | CC16: High | CD16: EX156 — Sweep Stroke Technique Drill | CF16: Critical | CG16: EX048 — Hill Repeats | CI16: High | CJ16: EX067 — MTB Attack Position Hold | CK16: Critical | CL16: EX124 — Power Hiking Technique | CN16: Critical | CO16: EX047 — Calf / Achilles Wall Stretch | CP16: High | CQ16: EX225 — V-Sit Hold
A17: High | B17: EX013 — Hip Circle (Band) | D17: High | E17: EX055 — Lateral Shuffle Sprint | G17: High | H17: EX063 — Terminal Knee Extension (TKE) | J17: High | K17: EX087 — Cable High-to-Low Chop | M17: High | N17: EX104 — Rice Bucket Drill | P17: High | Q17: EX020 — Nordic Hamstring Curl | S17: High | T17: EX096 — 90/90 Shoulder Stretch | V17: Medium | W17: EX089 — Hollow Body Hold | AA17: High | AB17: EX062 — Banded Hip Flexion (Standing) | AD17: High | AE17: EX048 — Hill Repeats | AG17: High | AH17: EX050 — Treadmill Incline Walk (Loaded Pack) | AI17: High | AJ17: EX078 — Single-Arm DB Row | AL17: Critical | AM17: EX163 — Canoe Portage Yoke Carry | AO17: High | AP17: EX043 — Single-Leg Balance Hold | AQ17: High | AR17: EX152 — Post-Hole Recovery Gait | AS17: High | AT17: EX177 — Open Water Mass Start Technique | AU17: High | AV17: EX003 — Romanian Deadlift (Barbell) | AX17: Critical | AY17: EX018 — Foam Roll (IT Band / Quads / Lats) | AZ17: High | BA17: EX060 — Single-Leg Press (Machine) | BC17: High | BD17: EX070 — Single-Leg Cycling Drill (Trainer) | BF17: High | BG17: EX010 — Rucking (Weighted Hike) | BH17: High | BI17: EX053 — Agility Ladder Drill | BK17: High | BL17: EX021 — Bulgarian Split Squat (DB) | BN17: High | BO17: EX196 — Obstacle Vault & Wall Traversal | BP17: High | BQ17: EX048 — Hill Repeats | BS17: High | BT17: EX048 — Hill Repeats | BU17: High | BV17: EX078 — Single-Arm DB Row | BX17: High | BY17: EX025 — Single-Leg Calf Raise (Loaded) | CA17: High | CB17: EX081 — Band Face Pull | CC17: High | CD17: EX158 — Whitewater Line Reading | CF17: Critical | CG17: EX052 — Downhill Running Technique Drill | CI17: High | CJ17: EX091 — Forward Stroke Technique Drill | CK17: Critical | CL17: EX047 — Calf / Achilles Wall Stretch | CN17: High | CO17: EX033 — Depth Drop (Eccentric Landing Practice) | CP17: High | CQ17: EX226 — L-Sit (Between Chairs / Parallettes)
A18: High | B18: EX014 — World's Greatest Stretch | D18: High | E18: EX059 — Neck Isometric Hold (Map Reading Position) | G18: High | H18: EX064 — Reverse Nordic Curl | J18: High | K18: EX089 — Hollow Body Hold | M18: High | N18: EX107 — One-Arm Assisted Hang | P18: High | Q18: EX025 — Single-Leg Calf Raise (Loaded) | S18: High | T18: EX084 — Scapular Depression Hold | AA18: High | AB18: EX063 — Terminal Knee Extension (TKE) | AD18: High | AE18: EX050 — Treadmill Incline Walk (Loaded Pack) | AG18: High | AH18: EX046 — Hip Flexor Lunge Stretch | AI18: High | AJ18: EX079 — Seated Cable Row (Narrow Grip) | AL18: High | AM18: EX160 — Seated Paddling Position Endurance | AO18: High | AP18: EX095 — Portage Carry Simulation | AQ18: High | AR18: EX073 — Threshold Intervals (Bike) | AS18: High | AT18: EX128 — Kicking Drill (Flutter / Frog) | AU18: High | AV18: EX004 — Single-Leg RDL (DB) | AX18: Critical | AY18: EX048 — Hill Repeats | AZ18: High | BA18: EX061 — Good Morning (Barbell) | BC18: High | BD18: EX019 — Barbell Hip Thrust | BF18: High | BG18: EX095 — Portage Carry Simulation | BH18: High | BI18: EX055 — Lateral Shuffle Sprint | BK18: High | BL18: EX007 — Box Jump | BN18: High | BO18: EX006 — Pull-Up (BW) | BP18: High | BQ18: EX049 — Strides (Flying Sprints) | BS18: High | BT18: EX049 — Strides (Flying Sprints) | BU18: High | BV18: EX019 — Barbell Hip Thrust | BX18: High | BY18: EX026 — Seated Calf Raise | CA18: High | CB18: EX078 — Single-Arm DB Row | CC18: High | CD18: EX009 — Farmer Carry | CF18: High | CG18: EX056 — Reactive Direction Change Drill | CI18: High | CJ18: EX090 — Paddling Ergometer Session | CK18: Critical | CL18: EX018 — Foam Roll (IT Band / Quads / Lats) | CN18: High | CO18: EX044 — BOSU Single-Leg Squat | CP18: High | CQ18: EX227 — Compression Tuck Hold
